<?xml version="1.0"?>
<robot xmlns:xacro="http://www.ros.org/wiki/xacro" name="robot">

    <xacro:include filename="include.xacro" />

    <link name="world" />

    <link name="base_link">
        <visual>
            <origin rpy="0 0 0" xyz="0 0 0.025" />
            <geometry>
                <box size="0.1 0.1 0.05" />
            </geometry>
            <material name="white" />
        </visual>
        <collision>
            <origin rpy="0 0 0" xyz="0 0 0.025" />
            <geometry>
                <box size="0.1 0.1 0.05" />
            </geometry>
        </collision>
        <xacro:inertial_box mass="0.5" x="0.1" y="0.1" z="0.05">
            <origin rpy="0 0 0" xyz="0 0 0" />
        </xacro:inertial_box>
    </link>

    <joint name="base_joint" type="fixed">
        <origin xyz="0 0 0" rpy="0 0 0" />
        <parent link="world" />
        <child link="base_link" />
    </joint>

    <link name="base_plate">
        <visual>
            <geometry>
                <cylinder radius="0.04" length="0.005" />
            </geometry>
            <origin rpy="0 0 0" xyz="0 0 0.0025" />
            <material name="white" />
        </visual>
        <collision>
            <geometry>
                <cylinder radius="0.04" length="0.005" />
            </geometry>
            <origin rpy="0 0 0" xyz="0 0 0.0025" />
        </collision>
        <xacro:inertial_cylinder mass="0.5" length="0.005" radius="0.04">
            <origin rpy="0 0 0" xyz="0 0 0" />
        </xacro:inertial_cylinder>
    </link>

    <joint name="base_plate_to_base_link" type="revolute">
        <axis xyz="0 0 1" />
        <limit effort="1000" lower="0" upper="3.1415" velocity="1" />
        <origin xyz="0 0 0.05" />
        <parent link="base_link" />
        <child link="base_plate" />
    </joint>

    <link name="base_plate_attachment">
        <visual>
            <geometry>
                <box size="0.025 0.04 0.05" />
            </geometry>
            <origin rpy="0 0 0" xyz="0 0 0.025" />
            <material name="white" />
        </visual>
        <collision>
            <geometry>
                <box size="0.025 0.04 0.05" />
            </geometry>
            <origin rpy="0 0 0" xyz="0 0 0.025" />
        </collision>
        <xacro:inertial_box mass="0.5" x="0.025" y="0.04" z="0.05">
            <origin rpy="0 0 0" xyz="0 0 0" />
        </xacro:inertial_box>
    </link>

    <joint name="base_plate_to_attachment" type="fixed">
        <origin xyz="0 0 0.005" />
        <parent link="base_plate" />
        <child link="base_plate_attachment" />
    </joint>

    <link name="mid_arm">
        <visual>
            <geometry>
                <box size="0.025 0.04 0.125" />
            </geometry>
            <origin rpy="-1.5707963 0 0" xyz="0 -0.05 0" />
            <material name="white" />
        </visual>
        <collision>
            <geometry>
                <box size="0.025 0.04 0.125" />
            </geometry>
            <origin rpy="-1.5707963 0 0" xyz="0 -0.05 0" />
        </collision>
        <xacro:inertial_box mass="0.5" x="0.025" y="0.04" z="0.125">
            <origin rpy="0 0 0" xyz="0 0 0" />
        </xacro:inertial_box>
    </link>

    <joint name="mid_arm_to_attachment" type="revolute">
        <axis xyz="-1 0 0" />
        <limit effort="1000" lower="0" upper="3.1415" velocity="1" />
        <origin xyz="0.025 0 0.025" />
        <parent link="base_plate_attachment" />
        <child link="mid_arm" />
    </joint>

    <link name="top_arm">
        <visual>
            <geometry>
                <box size="0.025 0.04 0.085" />
            </geometry>
            <origin rpy="-1.5707963 0 0" xyz="0 -0.025 0" />
            <material name="white" />
        </visual>
        <collision>
            <geometry>
                <box size="0.025 0.04 0.085" />
            </geometry>
            <origin rpy="-1.5707963 0 0" xyz="0 -0.025 0" />
        </collision>
        <xacro:inertial_box mass="0.5" x="0.025" y="0.04" z="0.085">
            <origin rpy="0 0 0" xyz="0 0 0" />
        </xacro:inertial_box>
    </link>

    <joint name="top_arm_to_mid_arm" type="revolute">
        <axis xyz="-1 0 0" />
        <limit effort="1000" lower="0" upper="3.1415" velocity="1" />
        <origin xyz="-0.025 -0.1 0" />
        <parent link="mid_arm" />
        <child link="top_arm" />
    </joint>

    <gazebo>
        <plugin name="gazebo_ros_joint_state_publisher"
            filename="libgazebo_ros_joint_state_publisher.so">
            <update_rate>30</update_rate>
            <joint_name>base_plate_to_base_link</joint_name>
            <joint_name>mid_arm_to_attachment</joint_name>
            <joint_name>top_arm_to_mid_arm</joint_name>
        </plugin>
    </gazebo>

    <!-- <xacro:include filename="gazebo.xacro" /> -->

</robot>