<?xml version="1.0"?>
<robot name="robot_arm">

  <link name="base_link">
    <visual>
      <geometry>
        <box size="0.1 0.1 0.05"/>
      </geometry>
      <origin rpy="0 0 0" xyz="0 0 0.025"/>
    </visual>
  </link>

  <link name="base_plate">
    <visual>
      <geometry>
        <cylinder radius="0.04" length="0.005"/>
      </geometry>
      <origin rpy="0 0 0" xyz="0 0 0.0025"/>
    </visual>
  </link>

  <joint name="base_plate_to_base_link" type="revolute">
    <axis xyz="0 0 1"/>
    <limit effort="1000" lower="0" upper="3.1415" velocity="1"/>
    <origin xyz="0 0 0.05"/>
    <parent link="base_link"/>
    <child link="base_plate"/>
  </joint>

  <link name="base_plate_attachment">
    <visual>
      <geometry>
        <box size="0.025 0.04 0.05"/>
      </geometry>
      <origin rpy="0 0 0" xyz="0 0 0.025"/>
    </visual>
  </link>

  <joint name="base_plate_to_attachment" type="fixed">
    <origin xyz="0 0 0.005"/>
    <parent link="base_plate"/>
    <child link="base_plate_attachment"/>
  </joint>

  <link name="mid_arm">
    <visual>
      <geometry>
        <box size="0.025 0.04 0.125"/>
      </geometry>
      <origin rpy="-1.5707963 0 0" xyz="0 -0.05 0"/>
    </visual>
  </link>

  <joint name="mid_arm_to_attachment" type="revolute">
    <axis xyz="-1 0 0"/>
    <limit effort="1000" lower="0" upper="3.1415" velocity="1"/>
    <origin xyz="0.025 0 0.025"/>
    <parent link="base_plate_attachment"/>
    <child link="mid_arm"/>
  </joint>

  <link name="top_arm">
    <visual>
      <geometry>
        <box size="0.025 0.04 0.085"/>
      </geometry>
      <origin rpy="-1.5707963 0 0" xyz="0 -0.025 0"/>
    </visual>
  </link>

  <joint name="top_arm_to_mid_arm" type="revolute">
    <axis xyz="-1 0 0"/>
    <limit effort="1000" lower="0" upper="3.1415" velocity="1"/>
    <origin xyz="-0.025 -0.1 0"/>
    <parent link="mid_arm"/>
    <child link="top_arm"/>
  </joint>

</robot>